Workbook

Sheet 00_README
A1: AI Marketing Platform - Production Engineering Execution Workbook
A3: Purpose | B3: Executable production master backlog and control workbook for two engineers. S0-S8 deliver Production GA; S9-S10 are post-GA growth expansion.
A5: Architecture | B5: Modular Monolith + Durable Workers + Ports/Adapters + tenant-safe RLS
A6: Primary stack | B6: Nuxt 4.5.x + Nuxt UI v4 + Motion for Vue + Node.js 24 LTS + FastAPI/Python 3.14 + Supabase Auth/Postgres/Storage/Queues + OpenAI + Meta APIs
A7: Security baseline | B7: OWASP ASVS 5.0 L2-oriented + OWASP API Security Top 10 + tenant isolation tests
A8: Planning policy | B8: S0-S5 core delivery; S6 Marketing OS; S7 feature completeness; S8 GA hardening/launch; S9-S10 growth formats/automation. Release gates, not dates, define readiness.
A9: Estimate semantics | B9: Task hours include implementation + owner tests. Peer-review, planning, support and unplanned debugging are expected to consume remaining sprint capacity.
A12: Planning Controls - blue cells are user-changeable inputs
A14: Kickoff date | B14: 46272 | C14: Change this to rebase all sprint dates.
A15: Sprint length (calendar days) | B15: 14 | C15: 2-week sprint.
A16: Capacity / programmer / sprint (h) | B16: 80 | C16: Nominal 10 workdays x 8h; reserve is shown separately.
A17: Target planned utilization | B17: 0.85 | C17: Guideline, not a hard formula. Early integration sprints may be denser.
A18: Number of sprints | B18: 11 | C18: S8 is Production GA target; S9-S10 continue growth without changing core launch gates.
A20: Calculated planned release | B20: =$B$14+($B$15*$B$18)-1 -> 46425 | C20: External approvals (especially Meta) can move public launch even when engineering is complete.
A21: Production GA target (S8 end) | B21: =$B$14+($B$15*9)-1 -> 46397 | C21: Calendar target only; RG gates and Meta approval can still block public launch.
A23: Workbook workflow
A25: 1 | B25: Read 00_README + companion DOCX before implementation.
A26: 2 | B26: Use 01_ROADMAP for sprint outcomes/capacity; 02_BACKLOG is task source of truth.
A27: 3 | B27: Move Status through Not Started -> Ready -> In Progress -> In Review -> Done; use Blocked with note/evidence.
A28: 4 | B28: A task is Done only when Acceptance Criteria + Test Evidence + relevant Release Gate requirements are satisfied.
A29: 5 | B29: Do not delete postponed work. Mark Deferred and create explicit follow-up/reason.
A30: 6 | B30: Architecture/security/provider contract changes require ADR/update, not silent implementation drift.
A33: Color conventions
A35: Blue | B35: User-changeable inputs
A36: Black | B36: Formulas / derived values
A37: Green | B37: Linked/imported sources
A38: Gray | B38: Static constants / specification text
A39: Orange | B39: Review / caution / external dependency
A40: Light red | B40: Error / blocker / high risk
A41: Purple | B41: Control / architecture logic
A42: Teal | B42: KPI / key anchor
A44: Audit i kodit dhe scope-it — 2026-09-07
A45: Rishikim i thelluar: 133 skedarë first-party dhe 185 task-e. 02_BACKLOG: Y zbatimi, Z kryer, AA mbetur, AB pranim/prova të kërkuara, AC prova reale, AD kod/gjetje. 7 In Review, 106 In Progress, 35 Not Started, 2 Blocked, 35 Deferred, 0 Done.
A46: Progress 2026-09-07: 31 task-e partial u përditësuan me implementim dhe prova të reja; 0 u quajtën Done pa gates. 42/42 unit/integration dhe 8/8 E2E kaluan, bashkë me lint/types. 15_GJETJET J–K tregon statusin aktual të 17 gjetjeve.
A47: Progress 2026-09-08: 44 task-e partial u përditësuan me implementim dhe prova të reja; 0 u quajtën Done pa gates. 47/47 unit/integration dhe 8/8 E2E kaluan, bashkë me lint/types. 15_GJETJET J–K tregon statusin aktual të 17 gjetjeve.
A48: Code audit + S0-A03 implementation 2026-09-08: 24 task-e janë kryer në kod dhe presin pranim/gate; 90 janë pjesërisht të implementuara; 34 pa filluar; 35 deferred; 2 blocked; 0 Done. Shiko 02_BACKLOG AE–AJ dhe 16_HANDOFF_2_DEV.

Sheet 01_ROADMAP
A1: 22-Week Master Roadmap - 2 Engineers (Production GA at S8)
A2: Dates/estimates remain the original plan. Status audited 2026-09-07; S8/S9/S10 counters repaired. In Review is not production acceptance; release gates remain mandatory.
A4: Sprint | B4: Weeks | C4: Start | D4: End | E4: Outcome | F4: Primary Gates | G4: A Hours | H4: B Hours | I4: Total Hours | J4: Capacity | K4: Utilization | L4: Buffer Hours | M4: Open P0 | N4: Task Count | O4: Done | P4: Sprint Status
A5: S0 | B5: Weeks 1-2 | C5: ='00_README'!$B$14+(ROW()-5)*'00_README'!$B$15 -> 46272 | D5: =C5+'00_README'!$B$15-1 -> 46285 | E5: Foundation secure skeleton | F5: RG-01 / RG-02 / RG-03 / RG-17 | G5: =SUMIFS('02_BACKLOG'!$K:$K,'02_BACKLOG'!$B:$B,$A5,'02_BACKLOG'!$I:$I,"Programmer A") -> 71 | H5: =SUMIFS('02_BACKLOG'!$K:$K,'02_BACKLOG'!$B:$B,$A5,'02_BACKLOG'!$I:$I,"Programmer B") -> 71 | I5: =G5+H5 -> 142 | J5: ='00_README'!$B$16*2 -> 160 | K5: =IFERROR(I5/J5,0) -> 0.8875 | L5: =J5-I5 -> 18 | M5: =COUNTIFS('02_BACKLOG'!$B:$B,$A5,'02_BACKLOG'!$H:$H,"P0",'02_BACKLOG'!$L:$L,"<>Done",'02_BACKLOG'!$L:$L,"<>Deferred") -> 14 | N5: =COUNTIF('02_BACKLOG'!$B:$B,$A5) -> 18 | O5: =COUNTIFS('02_BACKLOG'!$B:$B,$A5,'02_BACKLOG'!$L:$L,"Done") -> 0 | P5: =IF(COUNTIFS('02_BACKLOG'!$B:$B,$A5,'02_BACKLOG'!$L:$L,"Deferred")=N5,"Deferred",IF(O5=N5,"Done",IF(COUNTIFS('02_BACKLOG'!$B:$B,$A5,'02_BACKLOG'!$L:$L,"In Progress")+COUNTIFS('02_BACKLOG'!$B:$B,$A5,'02_BACKLOG'!$L:$L,"In Review")>0,"In Progress",IF(COUNTIFS('02_BACKLOG'!$B:$B,$A5,'02_BACKLOG'!$L:$L,"Blocked")>0,"Blocked","Planned")))) -> In Progress
A6: S1 | B6: Weeks 3-4 | C6: ='00_README'!$B$14+(ROW()-5)*'00_README'!$B$15 -> 46286 | D6: =C6+'00_README'!$B$15-1 -> 46299 | E6: Organizations, RBAC, onboarding and Brand Brain | F6: RG-02 / RG-03 / RG-17 | G6: =SUMIFS('02_BACKLOG'!$K:$K,'02_BACKLOG'!$B:$B,$A6,'02_BACKLOG'!$I:$I,"Programmer A") -> 72 | H6: =SUMIFS('02_BACKLOG'!$K:$K,'02_BACKLOG'!$B:$B,$A6,'02_BACKLOG'!$I:$I,"Programmer B") -> 71 | I6: =G6+H6 -> 143 | J6: ='00_README'!$B$16*2 -> 160 | K6: =IFERROR(I6/J6,0) -> 0.89375 | L6: =J6-I6 -> 17 | M6: =COUNTIFS('02_BACKLOG'!$B:$B,$A6,'02_BACKLOG'!$H:$H,"P0",'02_BACKLOG'!$L:$L,"<>Done",'02_BACKLOG'!$L:$L,"<>Deferred") -> 9 | N6: =COUNTIF('02_BACKLOG'!$B:$B,$A6) -> 18 | O6: =COUNTIFS('02_BACKLOG'!$B:$B,$A6,'02_BACKLOG'!$L:$L,"Done") -> 0 | P6: =IF(COUNTIFS('02_BACKLOG'!$B:$B,$A6,'02_BACKLOG'!$L:$L,"Deferred")=N6,"Deferred",IF(O6=N6,"Done",IF(COUNTIFS('02_BACKLOG'!$B:$B,$A6,'02_BACKLOG'!$L:$L,"In Progress")+COUNTIFS('02_BACKLOG'!$B:$B,$A6,'02_BACKLOG'!$L:$L,"In Review")>0,"In Progress",IF(COUNTIFS('02_BACKLOG'!$B:$B,$A6,'02_BACKLOG'!$L:$L,"Blocked")>0,"Blocked","Planned")))) -> In Progress
A7: S2 | B7: Weeks 5-6 | C7: ='00_README'!$B$14+(ROW()-5)*'00_README'!$B$15 -> 46300 | D7: =C7+'00_README'!$B$15-1 -> 46313 | E7: Media pipeline and Meta connection | F7: RG-04 / RG-05 / RG-17 | G7: =SUMIFS('02_BACKLOG'!$K:$K,'02_BACKLOG'!$B:$B,$A7,'02_BACKLOG'!$I:$I,"Programmer A") -> 75 | H7: =SUMIFS('02_BACKLOG'!$K:$K,'02_BACKLOG'!$B:$B,$A7,'02_BACKLOG'!$I:$I,"Programmer B") -> 70 | I7: =G7+H7 -> 145 | J7: ='00_README'!$B$16*2 -> 160 | K7: =IFERROR(I7/J7,0) -> 0.90625 | L7: =J7-I7 -> 15 | M7: =COUNTIFS('02_BACKLOG'!$B:$B,$A7,'02_BACKLOG'!$H:$H,"P0",'02_BACKLOG'!$L:$L,"<>Done",'02_BACKLOG'!$L:$L,"<>Deferred") -> 15 | N7: =COUNTIF('02_BACKLOG'!$B:$B,$A7) -> 18 | O7: =COUNTIFS('02_BACKLOG'!$B:$B,$A7,'02_BACKLOG'!$L:$L,"Done") -> 0 | P7: =IF(COUNTIFS('02_BACKLOG'!$B:$B,$A7,'02_BACKLOG'!$L:$L,"Deferred")=N7,"Deferred",IF(O7=N7,"Done",IF(COUNTIFS('02_BACKLOG'!$B:$B,$A7,'02_BACKLOG'!$L:$L,"In Progress")+COUNTIFS('02_BACKLOG'!$B:$B,$A7,'02_BACKLOG'!$L:$L,"In Review")>0,"In Progress",IF(COUNTIFS('02_BACKLOG'!$B:$B,$A7,'02_BACKLOG'!$L:$L,"Blocked")>0,"Blocked","Planned")))) -> In Progress
A8: S3 | B8: Weeks 7-8 | C8: ='00_README'!$B$14+(ROW()-5)*'00_README'!$B$15 -> 46314 | D8: =C8+'00_README'!$B$15-1 -> 46327 | E8: Grounded AI creation and Content Studio | F8: RG-06 / RG-16 / RG-17 | G8: =SUMIFS('02_BACKLOG'!$K:$K,'02_BACKLOG'!$B:$B,$A8,'02_BACKLOG'!$I:$I,"Programmer A") -> 74 | H8: =SUMIFS('02_BACKLOG'!$K:$K,'02_BACKLOG'!$B:$B,$A8,'02_BACKLOG'!$I:$I,"Programmer B") -> 76 | I8: =G8+H8 -> 150 | J8: ='00_README'!$B$16*2 -> 160 | K8: =IFERROR(I8/J8,0) -> 0.9375 | L8: =J8-I8 -> 10 | M8: =COUNTIFS('02_BACKLOG'!$B:$B,$A8,'02_BACKLOG'!$H:$H,"P0",'02_BACKLOG'!$L:$L,"<>Done",'02_BACKLOG'!$L:$L,"<>Deferred") -> 15 | N8: =COUNTIF('02_BACKLOG'!$B:$B,$A8) -> 19 | O8: =COUNTIFS('02_BACKLOG'!$B:$B,$A8,'02_BACKLOG'!$L:$L,"Done") -> 0 | P8: =IF(COUNTIFS('02_BACKLOG'!$B:$B,$A8,'02_BACKLOG'!$L:$L,"Deferred")=N8,"Deferred",IF(O8=N8,"Done",IF(COUNTIFS('02_BACKLOG'!$B:$B,$A8,'02_BACKLOG'!$L:$L,"In Progress")+COUNTIFS('02_BACKLOG'!$B:$B,$A8,'02_BACKLOG'!$L:$L,"In Review")>0,"In Progress",IF(COUNTIFS('02_BACKLOG'!$B:$B,$A8,'02_BACKLOG'!$L:$L,"Blocked")>0,"Blocked","Planned")))) -> In Progress
A9: S4 | B9: Weeks 9-10 | C9: ='00_README'!$B$14+(ROW()-5)*'00_README'!$B$15 -> 46328 | D9: =C9+'00_README'!$B$15-1 -> 46341 | E9: Approval, calendar and reliable publishing closed beta | F9: RG-07 / RG-14 / RG-17 | G9: =SUMIFS('02_BACKLOG'!$K:$K,'02_BACKLOG'!$B:$B,$A9,'02_BACKLOG'!$I:$I,"Programmer A") -> 72 | H9: =SUMIFS('02_BACKLOG'!$K:$K,'02_BACKLOG'!$B:$B,$A9,'02_BACKLOG'!$I:$I,"Programmer B") -> 73 | I9: =G9+H9 -> 145 | J9: ='00_README'!$B$16*2 -> 160 | K9: =IFERROR(I9/J9,0) -> 0.90625 | L9: =J9-I9 -> 15 | M9: =COUNTIFS('02_BACKLOG'!$B:$B,$A9,'02_BACKLOG'!$H:$H,"P0",'02_BACKLOG'!$L:$L,"<>Done",'02_BACKLOG'!$L:$L,"<>Deferred") -> 14 | N9: =COUNTIF('02_BACKLOG'!$B:$B,$A9) -> 18 | O9: =COUNTIFS('02_BACKLOG'!$B:$B,$A9,'02_BACKLOG'!$L:$L,"Done") -> 0 | P9: =IF(COUNTIFS('02_BACKLOG'!$B:$B,$A9,'02_BACKLOG'!$L:$L,"Deferred")=N9,"Deferred",IF(O9=N9,"Done",IF(COUNTIFS('02_BACKLOG'!$B:$B,$A9,'02_BACKLOG'!$L:$L,"In Progress")+COUNTIFS('02_BACKLOG'!$B:$B,$A9,'02_BACKLOG'!$L:$L,"In Review")>0,"In Progress",IF(COUNTIFS('02_BACKLOG'!$B:$B,$A9,'02_BACKLOG'!$L:$L,"Blocked")>0,"Blocked","Planned")))) -> In Progress
A10: S5 | B10: Weeks 11-12 | C10: ='00_README'!$B$14+(ROW()-5)*'00_README'!$B$15 -> 46342 | D10: =C10+'00_README'!$B$15-1 -> 46355 | E10: Analytics, billing, entitlements and hardening | F10: RG-08 / RG-11 / RG-12 | G10: =SUMIFS('02_BACKLOG'!$K:$K,'02_BACKLOG'!$B:$B,$A10,'02_BACKLOG'!$I:$I,"Programmer A") -> 73 | H10: =SUMIFS('02_BACKLOG'!$K:$K,'02_BACKLOG'!$B:$B,$A10,'02_BACKLOG'!$I:$I,"Programmer B") -> 69 | I10: =G10+H10 -> 142 | J10: ='00_README'!$B$16*2 -> 160 | K10: =IFERROR(I10/J10,0) -> 0.8875 | L10: =J10-I10 -> 18 | M10: =COUNTIFS('02_BACKLOG'!$B:$B,$A10,'02_BACKLOG'!$H:$H,"P0",'02_BACKLOG'!$L:$L,"<>Done",'02_BACKLOG'!$L:$L,"<>Deferred") -> 10 | N10: =COUNTIF('02_BACKLOG'!$B:$B,$A10) -> 18 | O10: =COUNTIFS('02_BACKLOG'!$B:$B,$A10,'02_BACKLOG'!$L:$L,"Done") -> 0 | P10: =IF(COUNTIFS('02_BACKLOG'!$B:$B,$A10,'02_BACKLOG'!$L:$L,"Deferred")=N10,"Deferred",IF(O10=N10,"Done",IF(COUNTIFS('02_BACKLOG'!$B:$B,$A10,'02_BACKLOG'!$L:$L,"In Progress")+COUNTIFS('02_BACKLOG'!$B:$B,$A10,'02_BACKLOG'!$L:$L,"In Review")>0,"In Progress",IF(COUNTIFS('02_BACKLOG'!$B:$B,$A10,'02_BACKLOG'!$L:$L,"Blocked")>0,"Blocked","Planned")))) -> In Progress
A11: S6 | B11: Weeks 13-14 | C11: ='00_README'!$B$14+(ROW()-5)*'00_README'!$B$15 -> 46356 | D11: =C11+'00_README'!$B$15-1 -> 46369 | E11: Marketing OS: strategy, campaigns, HQ, copilot, safety/cost foundation | F11: RG-15 / RG-16 / RG-17 / RG-18 | G11: =SUMIFS('02_BACKLOG'!$K:$K,'02_BACKLOG'!$B:$B,$A11,'02_BACKLOG'!$I:$I,"Programmer A") -> 81 | H11: =SUMIFS('02_BACKLOG'!$K:$K,'02_BACKLOG'!$B:$B,$A11,'02_BACKLOG'!$I:$I,"Programmer B") -> 71 | I11: =G11+H11 -> 152 | J11: ='00_README'!$B$16*2 -> 160 | K11: =IFERROR(I11/J11,0) -> 0.95 | L11: =J11-I11 -> 8 | M11: =COUNTIFS('02_BACKLOG'!$B:$B,$A11,'02_BACKLOG'!$H:$H,"P0",'02_BACKLOG'!$L:$L,"<>Done",'02_BACKLOG'!$L:$L,"<>Deferred") -> 10 | N11: =COUNTIF('02_BACKLOG'!$B:$B,$A11) -> 20 | O11: =COUNTIFS('02_BACKLOG'!$B:$B,$A11,'02_BACKLOG'!$L:$L,"Done") -> 0 | P11: =IF(COUNTIFS('02_BACKLOG'!$B:$B,$A11,'02_BACKLOG'!$L:$L,"Deferred")=N11,"Deferred",IF(O11=N11,"Done",IF(COUNTIFS('02_BACKLOG'!$B:$B,$A11,'02_BACKLOG'!$L:$L,"In Progress")+COUNTIFS('02_BACKLOG'!$B:$B,$A11,'02_BACKLOG'!$L:$L,"In Review")>0,"In Progress",IF(COUNTIFS('02_BACKLOG'!$B:$B,$A11,'02_BACKLOG'!$L:$L,"Blocked")>0,"Blocked","Planned")))) -> In Progress
A12: S7 | B12: Weeks 15-16 | C12: ='00_README'!$B$14+(ROW()-5)*'00_README'!$B$15 -> 46370 | D12: =C12+'00_README'!$B$15-1 -> 46383 | E12: GA feature completeness: learning, safety, admin, billing edge cases, UX reliability | F12: RG-08 / RG-15 / RG-16 / RG-17 / RG-18 | G12: =SUMIFS('02_BACKLOG'!$K:$K,'02_BACKLOG'!$B:$B,$A12,'02_BACKLOG'!$I:$I,"Programmer A") -> 83 | H12: =SUMIFS('02_BACKLOG'!$K:$K,'02_BACKLOG'!$B:$B,$A12,'02_BACKLOG'!$I:$I,"Programmer B") -> 70 | I12: =G12+H12 -> 153 | J12: ='00_README'!$B$16*2 -> 160 | K12: =IFERROR(I12/J12,0) -> 0.95625 | L12: =J12-I12 -> 7 | M12: =COUNTIFS('02_BACKLOG'!$B:$B,$A12,'02_BACKLOG'!$H:$H,"P0",'02_BACKLOG'!$L:$L,"<>Done",'02_BACKLOG'!$L:$L,"<>Deferred") -> 13 | N12: =COUNTIF('02_BACKLOG'!$B:$B,$A12) -> 20 | O12: =COUNTIFS('02_BACKLOG'!$B:$B,$A12,'02_BACKLOG'!$L:$L,"Done") -> 0 | P12: =IF(COUNTIFS('02_BACKLOG'!$B:$B,$A12,'02_BACKLOG'!$L:$L,"Deferred")=N12,"Deferred",IF(O12=N12,"Done",IF(COUNTIFS('02_BACKLOG'!$B:$B,$A12,'02_BACKLOG'!$L:$L,"In Progress")+COUNTIFS('02_BACKLOG'!$B:$B,$A12,'02_BACKLOG'!$L:$L,"In Review")>0,"In Progress",IF(COUNTIFS('02_BACKLOG'!$B:$B,$A12,'02_BACKLOG'!$L:$L,"Blocked")>0,"Blocked","Planned")))) -> In Progress
A13: S8 | B13: Weeks 17-18 | C13: ='00_README'!$B$14+(ROW()-5)*'00_README'!$B$15 -> 46384 | D13: =C13+'00_README'!$B$15-1 -> 46397 | E13: Production GA hardening, UAT, DR, Meta readiness and progressive launch | F13: RG-04 / RG-09 / RG-12 / RG-13 / RG-14 / RG-17 / RG-18 | G13: =SUMIFS('02_BACKLOG'!$K:$K,'02_BACKLOG'!$B:$B,$A13,'02_BACKLOG'!$I:$I,"Programmer A") -> 50 | H13: =SUMIFS('02_BACKLOG'!$K:$K,'02_BACKLOG'!$B:$B,$A13,'02_BACKLOG'!$I:$I,"Programmer B") -> 66 | I13: =G13+H13 -> 116 | J13: ='00_README'!$B$16*2 -> 160 | K13: =IFERROR(I13/J13,0) -> 0.725 | L13: =J13-I13 -> 44 | M13: =COUNTIFS('02_BACKLOG'!$B:$B,$A13,'02_BACKLOG'!$H:$H,"P0",'02_BACKLOG'!$L:$L,"<>Done",'02_BACKLOG'!$L:$L,"<>Deferred") -> 14 | N13: =COUNTIF('02_BACKLOG'!$B:$B,$A13) -> 16 | O13: =COUNTIFS('02_BACKLOG'!$B:$B,$A13,'02_BACKLOG'!$L:$L,"Done") -> 0 | P13: =IF(COUNTIFS('02_BACKLOG'!$B:$B,$A13,'02_BACKLOG'!$L:$L,"Deferred")=N13,"Deferred",IF(O13=N13,"Done",IF(COUNTIFS('02_BACKLOG'!$B:$B,$A13,'02_BACKLOG'!$L:$L,"In Progress")+COUNTIFS('02_BACKLOG'!$B:$B,$A13,'02_BACKLOG'!$L:$L,"In Review")>0,"In Progress",IF(COUNTIFS('02_BACKLOG'!$B:$B,$A13,'02_BACKLOG'!$L:$L,"Blocked")>0,"Blocked","Planned")))) -> In Progress
A14: S9 | B14: Weeks 19-20 | C14: ='00_README'!$B$14+(ROW()-5)*'00_README'!$B$15 -> 46398 | D14: =C14+'00_README'!$B$15-1 -> 46411 | E14: Growth formats and agency productivity | F14: RG-19 | G14: =SUMIFS('02_BACKLOG'!$K:$K,'02_BACKLOG'!$B:$B,$A14,'02_BACKLOG'!$I:$I,"Programmer A") -> 41 | H14: =SUMIFS('02_BACKLOG'!$K:$K,'02_BACKLOG'!$B:$B,$A14,'02_BACKLOG'!$I:$I,"Programmer B") -> 44 | I14: =G14+H14 -> 85 | J14: ='00_README'!$B$16*2 -> 160 | K14: =IFERROR(I14/J14,0) -> 0.53125 | L14: =J14-I14 -> 75 | M14: =COUNTIFS('02_BACKLOG'!$B:$B,$A14,'02_BACKLOG'!$H:$H,"P0",'02_BACKLOG'!$L:$L,"<>Done",'02_BACKLOG'!$L:$L,"<>Deferred") -> 0 | N14: =COUNTIF('02_BACKLOG'!$B:$B,$A14) -> 10 | O14: =COUNTIFS('02_BACKLOG'!$B:$B,$A14,'02_BACKLOG'!$L:$L,"Done") -> 0 | P14: =IF(COUNTIFS('02_BACKLOG'!$B:$B,$A14,'02_BACKLOG'!$L:$L,"Deferred")=N14,"Deferred",IF(O14=N14,"Done",IF(COUNTIFS('02_BACKLOG'!$B:$B,$A14,'02_BACKLOG'!$L:$L,"In Progress")+COUNTIFS('02_BACKLOG'!$B:$B,$A14,'02_BACKLOG'!$L:$L,"In Review")>0,"In Progress",IF(COUNTIFS('02_BACKLOG'!$B:$B,$A14,'02_BACKLOG'!$L:$L,"Blocked")>0,"Blocked","Planned")))) -> Deferred
A15: S10 | B15: Weeks 21-22 | C15: ='00_README'!$B$14+(ROW()-5)*'00_README'!$B$15 -> 46412 | D15: =C15+'00_README'!$B$15-1 -> 46425 | E15: Growth automation, reporting, multilingual and experiments | F15: Post-GA | G15: =SUMIFS('02_BACKLOG'!$K:$K,'02_BACKLOG'!$B:$B,$A15,'02_BACKLOG'!$I:$I,"Programmer A") -> 38 | H15: =SUMIFS('02_BACKLOG'!$K:$K,'02_BACKLOG'!$B:$B,$A15,'02_BACKLOG'!$I:$I,"Programmer B") -> 38 | I15: =G15+H15 -> 76 | J15: ='00_README'!$B$16*2 -> 160 | K15: =IFERROR(I15/J15,0) -> 0.475 | L15: =J15-I15 -> 84 | M15: =COUNTIFS('02_BACKLOG'!$B:$B,$A15,'02_BACKLOG'!$H:$H,"P0",'02_BACKLOG'!$L:$L,"<>Done",'02_BACKLOG'!$L:$L,"<>Deferred") -> 0 | N15: =COUNTIF('02_BACKLOG'!$B:$B,$A15) -> 10 | O15: =COUNTIFS('02_BACKLOG'!$B:$B,$A15,'02_BACKLOG'!$L:$L,"Done") -> 0 | P15: =IF(COUNTIFS('02_BACKLOG'!$B:$B,$A15,'02_BACKLOG'!$L:$L,"Deferred")=N15,"Deferred",IF(O15=N15,"Done",IF(COUNTIFS('02_BACKLOG'!$B:$B,$A15,'02_BACKLOG'!$L:$L,"In Progress")+COUNTIFS('02_BACKLOG'!$B:$B,$A15,'02_BACKLOG'!$L:$L,"In Review")>0,"In Progress",IF(COUNTIFS('02_BACKLOG'!$B:$B,$A15,'02_BACKLOG'!$L:$L,"Blocked")>0,"Blocked","Planned")))) -> Deferred
A17: TOTAL | G17: =SUM(G5:G15) -> 730 | H17: =SUM(H5:H15) -> 719 | I17: =SUM(I5:I15) -> 1449 | J17: =SUM(J5:J15) -> 1760 | K17: =IFERROR(I17/J17,0) -> 0.82329545 | L17: =SUM(L5:L15) -> 311 | M17: =SUM(M5:M15) -> 114 | N17: =SUM(N5:N15) -> 185 | O17: =SUM(O5:O15) -> 0 | P17: Overall plan — gates open

Sheet 02_BACKLOG
A1: Engineering Master Backlog - 185 Exact Tasks
A2: Implementation master: every task has contractual acceptance criteria. S0-S8 = Production GA; S9-S10 = Growth expansion. Filter by Layer, Surface, Scope, Sprint, Owner and Gate.
A4: Task ID | B4: Sprint | C4: Epic | D4: Task | E4: Implementation Detail | F4: Acceptance Criteria | G4: Dependencies | H4: Priority | I4: Owner | J4: Reviewer | K4: Est. Hours | L4: Status | M4: Test Evidence | N4: Release Gate | O4: Security / Data Notes | P4: Deliverable / Artifact | Q4: Planned Start | R4: Planned End | S4: PR / Evidence Link | T4: Layer / Workstream | U4: Product Surface | V4: Release Scope | W4: Nuxt UI / UX Specification | X4: Verification Type | Y4: Vlerësimi i zbatimit | Z4: Çfarë është kryer realisht | AA4: Çfarë mbetet për këtë task | AB4: Prova / kushti për mbyllje | AC4: Provat e kryera dhe kufijtë | AD4: Kodi / gjetjet e auditit | AE4: Gjendja reale e kodit — 2026-09-08 | AF4: Kërkon zhvillim tjetër? | AG4: Kërkon provë / gate? | AH4: Hapi i ardhshëm konkret | AI4: Evidenca e auditit të ri | AJ4: Pronari / reviewer për handoff
A5: S0-A01 | B5: S0 | C5: Architecture | D5: Record ADR-001 modular monolith baseline | E5: Create ADR template and ADR-001 with modules, dependency direction, service-extraction triggers and deployment units. | F5: ADR accepted; no unresolved architecture blocker; repo links ADR from README. | G5: None | H5: P0 | I5: Programmer A | J5: Programmer B | K5: 6 | L5: In Review | M5: Architecture review checklist | N5: RG-01 | O5: Defines trust/service boundaries. | P5: docs/adr/ADR-001.md | Q5: =INDEX('01_ROADMAP'!$C$5:$C$15,MATCH(B5,'01_ROADMAP'!$A$5:$A$15,0)) -> 46272 | R5: =INDEX('01_ROADMAP'!$D$5:$D$15,MATCH(B5,'01_ROADMAP'!$A$5:$A$15,0)) -> 46285 | S5: docs/backlog-partial-progress-2026-09-08.json#S0-A01 | T5: SETUP/PLATFORM | U5: Platform | V5: GA | W5: N/A / API-domain contract consumed by frontend where applicable. | X5: Acceptance Criteria + Test Evidence + Release Gate | Y5: Implementuar — në pranim | Z5: ADR-002 është Accepted dhe dokumenton modular monolith Nuxt/Nitro/PostgreSQL, kufijtë e moduleve, worker-in e ndarë dhe deployment-in. ADR-001 është Superseded; README/status/handoff/validation janë sinkronizuar. Klasifikimi 2026-09-08: ADR dhe lidhjet e dokumentimit janë implementuar; pret architecture review/RG-01. | AA5: Mbeten architecture review checklist, prova e deployment-it të ndarë dhe RG-01. Follow-up-et RLS/runtime-role/observability të ADR-002 nuk janë gates të kaluara. | AB5: Prova e kërkuar nga backlog-u: Architecture review checklist Kriteri për t'u verifikuar (nuk deklarohet i kaluar): ADR accepted; no unresolved architecture blocker; repo links ADR from README. DA-13: Content review në local bypass dhe public verification, pa përshkrime të shërbimeve të paaktivizuara si aktive; operatori pranon versionin publik. Pranimi kërkon edhe gate-et: RG-01. Asnjë gate nuk është shënuar Passed nga ky audit. | AC5: ADR-002 + kontroll statik i dokumenteve; lint dhe TypeScript kaluan. Nuk ka review sign-off të ekipit ose hosted release gate. | AD5: docs/adr/ADR-002-production-modular-monolith.md docs/adr/ADR-001-frontend-demo.md README.md docs/FRONTEND-STATUS.md docs/BACKEND-HANDOFF.md | AE5: Kryer në kod — pret pranim/gate | AF5: Jo për scope-in e rreshtit | AG5: Po | AH5: Mbeten architecture review checklist, prova e deployment-it të ndarë dhe RG-01. Follow-up-et RLS/runtime-role/observability të ADR-002 nuk janë gates të kaluara. | AI5: docs/backlog-code-handoff-2026-09-08.json#S0-A01 | AJ5: Programmer A / review: Programmer B
A6: S0-A02 | B6: S0 | C6: Repository | D6: Bootstrap backend/worker packages | E6: Create FastAPI API and worker packages, src module convention, shared config package and health endpoints. | F6: API/worker start locally; module import rule documented; /health/live returns 200. | G6: S0-A01 | H6: P0 | I6: Programmer A | J6: Programmer B | K6: 8 | L6: In Review | M6: pytest smoke + container smoke | N6: RG-01 | O6: No provider SDK in domain package. | P6: apps/api + apps/worker | Q6: =INDEX('01_ROADMAP'!$C$5:$C$15,MATCH(B6,'01_ROADMAP'!$A$5:$A$15,0)) -> 46272 | R6: =INDEX('01_ROADMAP'!$D$5:$D$15,MATCH(B6,'01_ROADMAP'!$A$5:$A$15,0)) -> 46285 | S6: docs/backlog-partial-progress-2026-09-08.json#S0-A02 | T6: SETUP/PLATFORM | U6: Platform | V6: GA | W6: N/A / API-domain contract consumed by frontend where applicable. | X6: Acceptance Criteria + Test Evidence + Release Gate | Y6: Implementuar — në pranim | Z6: API Nitro dhe publisher funksionojnë nga i njëjti artefakt; /api/health/live dhe /api/health/ready ekzistojnë. Readiness kontrollon DB, migrimin 0013, heartbeat-in kur publishing aktivizohet dhe queue age. Kufijtë e moduleve janë në ADR-002. Klasifikimi 2026-09-08: API dhe worker-i nisen si role të ndara në container; liveness dhe container smoke kalojnë; pret RG-01. | AA6: Duhet container/process smoke me publisher të aktivizuar, deployment i veçantë i worker-it dhe RG-01; Meta App mungon për një start real publishing. | AB6: Prova e kërkuar nga backlog-u: pytest smoke + container smoke Kriteri për t'u verifikuar (nuk deklarohet i kaluar): API/worker start locally; module import rule documented; /health/live returns 200. Pranimi kërkon edhe gate-et: RG-01. Asnjë gate nuk është shënuar Passed nga ky audit. | AC6: Health live/ready kthyen 200 lokalisht; migrimet 0001–0013 u aplikuan. Nuk u krye container smoke. Validimi 2026-09-08: image-i production me Node 24.20.0 u ngrit healthy si web dhe publisher i veçantë; /api/health/live ktheu 200 brenda container-it. | AD6: apps/web/server/api/health/live.get.ts apps/web/server/api/health/ready.get.ts apps/web/server/plugins/publisher.ts docs/adr/ADR-002-production-modular-monolith.md Dockerfile; compose.yaml; apps/web/server/plugins/publisher.ts; apps/web/server/api/health/live.get.ts; docs/DEPLOYMENT.md | AE6: Kryer në kod — pret pranim/gate | AF6: Jo për scope-in e rreshtit | AG6: Po | AH6: Duhet container/process smoke me publisher të aktivizuar, deployment i veçantë i worker-it dhe RG-01; Meta App mungon për një start real publishing. | AI6: docs/backlog-code-handoff-2026-09-08.json#S0-A02 | AJ6: Programmer A / review: Programmer B
A7: S0-A03 | B7: S0 | C7: Backend Tooling | D7: Pin Node.js 24.20.0 and npm 11.19.0 toolchain | E7: Apply ADR-002's Nitro/TypeScript replacement: pin runtime/package manager, enforce the npm lockfile, ESLint/type policy, deterministic Vitest settings, a versioned pre-commit hook and identical local/CI quality commands. | F7: Clean npm ci from lock; exact toolchain check plus lint/type/unit commands reproducible locally, in the Docker clean-room target and CI. | G7: S0-A02 | H7: P0 | I7: Programmer A | J7: Programmer B | K7: 5 | L7: In Review | M7: Clean Node 24.20.0 Docker build: toolchain/lint/type/24 unit/28 integration/build passed | N7: RG-01 | O7: Dependency lock and supply-chain baseline; Docker image pinned by version and digest. | P7: package manifests + package-lock + .npmrc + hooks + docs/TOOLCHAIN.md | Q7: =INDEX('01_ROADMAP'!$C$5:$C$15,MATCH(B7,'01_ROADMAP'!$A$5:$A$15,0)) -> 46272 | R7: =INDEX('01_ROADMAP'!$D$5:$D$15,MATCH(B7,'01_ROADMAP'!$A$5:$A$15,0)) -> 46285 | S7: docs/S0-A03-REPORT-SQ.md | T7: SETUP/PLATFORM | U7: AI Platform | V7: GA | W7: N/A / API-domain contract consumed by frontend where applicable. | X7: Acceptance Criteria + Test Evidence + Release Gate | Y7: Implementuar — në pranim | Z7: ADR-002 maps the unimplemented Python backend to Nitro/TypeScript. Node.js 24.20.0/npm 11.19.0, engine enforcement, npm lockfile, shared quality commands, deterministic Vitest, pre-commit, CI parity and Docker quality gate are implemented. | AA7: Kodi i task-ut nuk ka punë të mbetur. Ekzekuto hosted GitHub Actions; Programmer B konfirmon required check dhe regjistron RG-01 para statusit Done. | AB7: Fresh environment build: clean npm ci; exact toolchain, lint, typecheck, unit/integration and production build; same gate in CI; reviewer/RG-01 sign-off. | AC7: Validimi 2026-09-08: Docker clean-room me Node.js 24.20.0/npm 11.19.0 instaloi 991 paketa nga lockfile; toolchain/lint/typecheck kaluan; 24/24 unit dhe 28/28 PostgreSQL integration tests kaluan; Nuxt/Nitro production build përfundoi. Hosted CI/reviewer sign-off nuk u deklarua lokalisht. | AD7: .nvmrc; .npmrc; package.json; package-lock.json; apps/web/package.json; apps/web/vitest.config.ts; .githooks/pre-commit; scripts/check-toolchain.mjs; scripts/install-git-hooks.mjs; Dockerfile; .github/workflows/frontend.yml; docs/TOOLCHAIN.md; docs/VALIDATION.md; docs/S0-A03-REPORT-SQ.md | AE7: Kryer në kod — pret pranim/gate | AF7: Jo për scope-in e rreshtit | AG7: Po — hosted CI/reviewer | AH7: Ekzekuto hosted GitHub Actions; Programmer B konfirmon required check dhe regjistron RG-01 para statusit Done. | AI7: docs/S0-A03-REPORT-SQ.md | AJ7: Programmer A / review: Programmer B
A8: S0-A04 | B8: S0 | C8: Database | D8: Bootstrap PostgreSQL environments and migrations | E8: Create local/staging/prod conventions, versioned SQL migrations, separate migration/runtime database roles and a repeatable empty-database strategy. | F8: Local reset succeeds from zero; migration/runtime roles are separated; staging dry-run documented; no production credentials committed. | G8: S0-A01 | H8: P0 | I8: Programmer A | J8: Programmer B | K8: 8 | L8: In Review | M8: PostgreSQL empty-database reset + migration/runtime role smoke | N8: RG-01 | O8: Environment isolation; secret handling. | P8: Docker/ migrations + role provisioning + deploy runbook | Q8: =INDEX('01_ROADMAP'!$C$5:$C$15,MATCH(B8,'01_ROADMAP'!$A$5:$A$15,0)) -> 46272 | R8: =INDEX('01_ROADMAP'!$D$5:$D$15,MATCH(B8,'01_ROADMAP'!$A$5:$A$15,0)) -> 46285 | S8: docs/backlog-deep-audit-2026-09-07.json#S0-A04 | T8: DATABASE | U8: Platform | V8: GA | W8: N/A / API-domain contract consumed by frontend where applicable. | X8: Acceptance Criteria + Test Evidence + Release Gate | Y8: Implementuar — në pranim | Z8: PostgreSQL në Docker, migrime SQL me checksum/transaksion/advisory lock, target i veçantë migrimi dhe rol runtime pa DDL. Klasifikimi 2026-09-08: PostgreSQL reset/migrimet dhe rolet migration/runtime janë implementuar e provuar; pret staging/RG-01. | AA8: Ekzekuto migration dry-run në staging me role të ndara dhe regjistro RG-01; kjo kërkon mjedisin e hostuar. | AB8: Prova e kërkuar: empty-database migration smoke, runtime DDL-deny, staging dry-run dhe RG-01. | AC8: hq-deep-audit-unit.log: schema testuese PostgreSQL nga migrimet, JPEG decode/EXIF, ownership checks, token encryption/transport dhe signed media. Nuk është RLS/ASVS/Meta OAuth acceptance e plotë. Validimi 2026-09-08: target-i migrations aplikoi migrimet 0001–0013 mbi databazën e përkohshme rrit_migration_smoke nga zero dhe u verifikuan 13 rreshta në schema_migrations. Staging dry-run mbetet. Validimi 2026-09-08: target-i migrations aplikoi migrimet 0001–0013 mbi databazën e përkohshme rrit_migration_smoke nga zero dhe u verifikuan 13 rreshta në schema_migrations. Roli runtime lexoi skemën dhe kaloi 8/8 E2E, ndërsa CREATE TABLE u refuzua me permission denied. Staging dry-run mbetet. Validimi 2026-09-08: target-i migrations aplikoi migrimet 0001–0015 dhe migrimet u provuan nga zero në skemën e izoluar të integration suite. Roli runtime lexoi skemën dhe kaloi 8/8 E2E, ndërsa CREATE TABLE u refuzua me permission denied. Staging dry-run mbetet. Validimi 2026-09-08: target-i migrations aplikoi migrimet 0001–0017 dhe migrimet u provuan nga zero në skemën e izoluar të integration suite. Roli runtime lexoi skemën dhe kaloi 8/8 E2E, ndërsa CREATE TABLE u refuzua me permission denied. Staging dry-run mbetet. | AD8: compose.yaml apps/web/scripts/migrate.mjs apps/web/database/migrations apps/web/tests/integration/server.test.ts Dockerfile; compose.yaml; apps/web/scripts/migrate.mjs; apps/web/database/migrations; docs/DEPLOYMENT.md Dockerfile; compose.yaml; infra/postgres/provision-runtime.sh; scripts/setup-local.mjs; apps/web/scripts/migrate.mjs; apps/web/database/migrations; docs/DEPLOYMENT.md | AE8: Kryer në kod — pret pranim/gate | AF8: Jo për scope-in e rreshtit | AG8: Po | AH8: Ekzekuto migration dry-run në staging me role të ndara dhe regjistro RG-01; kjo kërkon mjedisin e hostuar. | AI8: docs/backlog-code-handoff-2026-09-08.json#S0-A04 | AJ8: Programmer A / review: Programmer B
A9: S0-A05 | B9: S0 | C9: Tenancy | D9: Implement tenant DB context and RLS helpers | E9: Create app_runtime role approach, transaction-scoped app.user_id/app.organization_id context and reusable RLS policy helpers. | F9: Cross-tenant query denied under runtime role; missing tenant context returns no tenant rows/fails safely. | G9: S0-A04 | H9: P0 | I9: Programmer A | J9: Programmer B | K9: 10 | L9: Not Started | M9: SQL integration negative tests | N9: RG-02 | O9: Core tenant isolation boundary. | P9: RLS helper migration/tests | Q9: =INDEX('01_ROADMAP'!$C$5:$C$15,MATCH(B9,'01_ROADMAP'!$A$5:$A$15,0)) -> 46272 | R9: =INDEX('01_ROADMAP'!$D$5:$D$15,MATCH(B9,'01_ROADMAP'!$A$5:$A$15,0)) -> 46285 | S9: docs/backlog-deep-audit-2026-09-07.json#S0-A05 | T9: FRONTEND | U9: Platform | V9: GA | W9: N/A / API-domain contract consumed by frontend where applicable. | X9: Acceptance Criteria + Test Evidence + Release Gate | Y9: Pa filluar | Z9: Izolimi aktual bëhet me owner_id/business_id në query-t e aplikacionit. | AA9: 1. Krijo rol runtime pa privilegje të migrimit dhe tenant context për transaksion; aktivizo RLS/policies në çdo tabelë tenant. Provo mungesën e context-it dhe cross-tenant read/write/delete. | AB9: Prova e kërkuar nga backlog-u: SQL integration negative tests Kriteri për t'u verifikuar (nuk deklarohet i kaluar): Cross-tenant query denied under runtime role; missing tenant context returns no tenant rows/fails safely. Pranimi kërkon edhe gate-et: RG-02. Asnjë gate nuk është shënuar Passed nga ky audit. | AC9: U rishikuan kodi/artefaktet dhe u kërkua implementimi i kësaj detyre. Nuk ka provë të ekzekutuar specifike që mbyll të gjithë kriterin; kontrollet globale nuk e zëvendësojnë atë. | AD9: apps/web/server/utils/workspaces.ts apps/web/database/migrations | AE9: Pa filluar | AF9: Po | AG9: Po, pas implementimit | AH9: Krijo rol runtime pa privilegje të migrimit dhe tenant context për transaksion; aktivizo RLS/policies në çdo tabelë tenant. Provo mungesën e context-it dhe cross-tenant read/write/delete. | AI9: docs/backlog-code-handoff-2026-09-08.json#S0-A05 | AJ9: Programmer A / review: Programmer B
A10: S0-A06 | B10: S0 | C10: Tenancy | D10: Build RLS CI test harness | E10: Create fixtures for Org A/B/users and reusable allow/deny assertions; make RLS suite required in CI. | F10: Representative read/write/delete cross-tenant tests fail before policy and pass after; CI blocks regression. | G10: S0-A05 | H10: P0 | I10: Programmer A | J10: Programmer B | K10: 8 | L10: Not Started | M10: pytest DB/RLS suite | N10: RG-02 | O10: Automated isolation verification. | P10: tests/security/rls | Q10: =INDEX('01_ROADMAP'!$C$5:$C$15,MATCH(B10,'01_ROADMAP'!$A$5:$A$15,0)) -> 46272 | R10: =INDEX('01_ROADMAP'!$D$5:$D$15,MATCH(B10,'01_ROADMAP'!$A$5:$A$15,0)) -> 46285 | S10: docs/backlog-deep-audit-2026-09-07.json#S0-A06 | T10: DATABASE | U10: Platform | V10: GA | W10: N/A / API-domain contract consumed by frontend where applicable. | X10: Acceptance Criteria + Test Evidence + Release Gate | Y10: Pa filluar | Z10: Izolimi aktual bëhet me owner_id/business_id në query-t e aplikacionit. | AA10: 1. Ndërto fixture Org A/B dhe helper allow/deny nën rolin runtime; lidhe suite RLS me required CI. Hiq një policy qëllimisht dhe provo se CI dështon. | AB10: Prova e kërkuar nga backlog-u: pytest DB/RLS suite Kriteri për t'u verifikuar (nuk deklarohet i kaluar): Representative read/write/delete cross-tenant tests fail before policy and pass after; CI blocks regression. Pranimi kërkon edhe gate-et: RG-02. Asnjë gate nuk është shënuar Passed nga ky audit. | AC10: U rishikuan kodi/artefaktet dhe u kërkua implementimi i kësaj detyre. Nuk ka provë të ekzekutuar specifike që mbyll të gjithë kriterin; kontrollet globale nuk e zëvendësojnë atë. | AD10: apps/web/server/utils/workspaces.ts apps/web/database/migrations | AE10: Pa filluar | AF10: Po | AG10: Po, pas implementimit | AH10: Ndërto fixture Org A/B dhe helper allow/deny nën rolin runtime; lidhe suite RLS me required CI. Hiq një policy qëllimisht dhe provo se CI dështon. | AI10: docs/backlog-code-handoff-2026-09-08.json#S0-A06 | AJ10: Programmer A / review: Programmer B
A11: S0-A07 | B11: S0 | C11: Authentication | D11: Verify Better Auth sessions in Nitro | E11: Validate opaque database sessions through Better Auth on every protected Nitro endpoint; enforce expiry, revocation, forged-cookie rejection and exact-origin checks for mutations. | F11: Valid session accepted; expired, revoked and forged session rejected with AUTH_REQUIRED; untrusted mutation origin rejected with ORIGIN_REJECTED. | G11: S0-A02,S0-A04 | H11: P0 | I11: Programmer A | J11: Programmer B | K11: 8 | L11: In Review | M11: Production-container auth session E2E | N11: RG-03 | O11: No token body logged. | P11: Central session/origin guard + auth acceptance suite | Q11: =INDEX('01_ROADMAP'!$C$5:$C$15,MATCH(B11,'01_ROADMAP'!$A$5:$A$15,0)) -> 46272 | R11: =INDEX('01_ROADMAP'!$D$5:$D$15,MATCH(B11,'01_ROADMAP'!$A$5:$A$15,0)) -> 46285 | S11: docs/backlog-deep-audit-2026-09-07.json#S0-A07 | T11: SECURITY | U11: Auth | V11: GA | W11: N/A / API-domain contract consumed by frontend where applicable. | X11: Acceptance Criteria + Test Evidence + Release Gate | Y11: Implementuar — në pranim | Z11: Better Auth me sessione opaque në PostgreSQL, cookie cache të çaktivizuar, skadim 7-ditor, revokim pas logout/reset dhe guard i përbashkët për API-të. Klasifikimi 2026-09-08: Better Auth session guard pranon sesionin valid dhe refuzon forged/revoked/expired me kode stabile; pret RG-03. | AA11: Ekzekuto suite-n në hosted CI/public staging dhe regjistro security review/RG-03. | AB11: Prova e kërkuar: valid/forged/revoked/expired session E2E, origin rejection dhe RG-03. | AC11: U rishikuan kodi/artefaktet dhe u kërkua implementimi i kësaj detyre. Nuk ka provë të ekzekutuar specifike që mbyll të gjithë kriterin; kontrollet globale nuk e zëvendësojnë atë. Validimi 2026-09-08: E2E mbi container-in production provoi sesion valid, cookie të falsifikuar, logout/revokim dhe expiresAt të kaluar; përgjigjja e mbrojtur ktheu AUTH_REQUIRED. Origin-i i huaj u refuzua me ORIGIN_REJECTED. | AD11: apps/web/server/utils/auth.ts apps/web/server/utils/access.ts apps/web/tests/e2e/local-registration.spec.ts apps/web/server/utils/auth.ts; apps/web/server/utils/access.ts; apps/web/server/utils/auth-configuration.ts; apps/web/tests/e2e/auth-session.spec.ts; apps/web/tests/e2e/local-registration.spec.ts | AE11: Kryer në kod — pret pranim/gate | AF11: Jo për scope-in e rreshtit | AG11: Po | AH11: Ekzekuto suite-n në hosted CI/public staging dhe regjistro security review/RG-03. | AI11: docs/backlog-code-handoff-2026-09-08.json#S0-A07 | AJ11: Programmer A / review: Programmer B
A12: S0-A08 | B12: S0 | C12: Async Platform | D12: Create durable queue/outbox skeleton | E12: Enable Supabase Queues/pgmq locally, define JobEnvelope, outbox table and generic idempotent consumer base. | F12: Test event commits with outbox; dispatcher enqueues; worker consumes once logically under duplicate delivery. | G12: S0-A04 | H12: P0 | I12: Programmer A | J12: Programmer B | K12: 10 | L12: In Review | M12: queue duplicate/crash tests | N12: RG-01 | O12: Queue not exposed to browser. | P12: queue/outbox framework | Q12: =INDEX('01_ROADMAP'!$C$5:$C$15,MATCH(B12,'01_ROADMAP'!$A$5:$A$15,0)) -> 46272 | R12: =INDEX('01_ROADMAP'!$D$5:$D$15,MATCH(B12,'01_ROADMAP'!$A$5:$A$15,0)) -> 46285 | S12: docs/backlog-deep-audit-2026-09-07.json#S0-A08 | T12: SETUP/PLATFORM | U12: Platform | V12: GA | W12: N/A / API-domain contract consumed by frontend where applicable. | X12: Acceptance Criteria + Test Evidence + Release Gate | Y12: Implementuar — në pranim | Z12: Outbox PostgreSQL me envelope/version/dedupe, claim FOR UPDATE SKIP LOCKED, lease recovery, receipt të konsumit dhe transaksion të njëjtë për efektet DB. Klasifikimi 2026-09-08: Outbox-i transaksional, claim me lease/SKIP LOCKED, deduplication dhe crash recovery janë implementuar; pret RG-01. | AA12: Ekzekuto hosted CI/container failure rehearsal dhe regjistro RG-01; adapterët me side-effect të jashtëm vazhdojnë të përdorin idempotency/reconciliation specifik. | AB12: Prova e kërkuar: queue duplicate/crash/concurrency tests, container smoke dhe RG-01. | AC12: U rishikuan kodi/artefaktet dhe u kërkua implementimi i kësaj detyre. Nuk ka provë të ekzekutuar specifike që mbyll të gjithë kriterin; kontrollet globale nuk e zëvendësojnë atë. Validimi 2026-09-08: migrimi 0014 krijoi JobEnvelope/outbox receipts; testet provuan commit/rollback atomik, dedupe, dy consumer-a paralelë me vetëm një efekt dhe rikuperim të claim-it stale. Readiness production kërkon migrimin 0014. Validimi 2026-09-08: migrimi 0014 krijoi JobEnvelope/outbox receipts; testet provuan commit/rollback atomik, dedupe, dy consumer-a paralelë me vetëm një efekt dhe rikuperim të claim-it stale. Readiness production kërkon migrimin minimal aktual 0015. Validimi 2026-09-08: migrimi 0014 krijoi JobEnvelope/outbox receipts; testet provuan commit/rollback atomik, dedupe, dy consumer-a paralelë me vetëm një efekt dhe rikuperim të claim-it stale. Readiness production kërkon migrimin minimal aktual 0017. | AD12: apps/web/database/migrations/0004_trials_and_social.sql apps/web/server/utils/publishing.ts apps/web/database/migrations/0014_durable_outbox.sql; apps/web/server/utils/outbox.ts; apps/web/tests/integration/server.test.ts; apps/web/server/api/health/ready.get.ts | AE12: Kryer në kod — pret pranim/gate | AF12: Jo për scope-in e rreshtit | AG12: Po | AH12: Ekzekuto hosted CI/container failure rehearsal dhe regjistro RG-01; adapterët me side-effect të jashtëm vazhdojnë të përdorin idempotency/reconciliation specifik. | AI12: docs/backlog-code-handoff-2026-09-08.json#S0-A08 | AJ12: Programmer A / review: Programmer B
A13: S0-A09 | B13: S0 | C13: CI/CD | D13: Create backend/security CI gates | E13: Add lint, types, unit, DB reset/RLS, secret scan, dependency scan and container build jobs with caching. | F13: PR cannot merge when any gate fails; CI artifacts include test reports. | G13: S0-A03,S0-A04,S0-A06 | H13: P0 | I13: Programmer A | J13: Programmer B | K13: 8 | L13: In Progress | M13: Deliberate failing PR checks | N13: RG-01 | O13: Secure SDLC baseline. | P13: .github/workflows backend | Q13: =INDEX('01_ROADMAP'!$C$5:$C$15,MATCH(B13,'01_ROADMAP'!$A$5:$A$15,0)) -> 46272 | R13: =INDEX('01_ROADMAP'!$D$5:$D$15,MATCH(B13,'01_ROADMAP'!$A$5:$A$15,0)) -> 46285 | S13: docs/backlog-partial-progress-2026-09-08.json#S0-A09 | T13: SECURITY | U13: Security | V13: GA | W13: N/A / API-domain contract consumed by frontend where applicable. | X13: Acceptance Criteria + Test Evidence + Release Gate | Y13: Pjesërisht | Z13: CI provisionon PostgreSQL, env vetëm testues, aplikon migrimet, ndërton output-in, pret readiness, ekzekuton lint/type/unit/E2E/audit dhe ngarkon artefakte. | AA13: Mbeten run hosted, required branch checks, deliberate failing PR dhe gates RLS/secret/container. Workspace nuk ka .git, prandaj merge blocking nuk mund të provohet lokalisht. | AB13: Prova e kërkuar nga backlog-u: Deliberate failing PR checks Kriteri për t'u verifikuar (nuk deklarohet i kaluar): PR cannot merge when any gate fails; CI artifacts include test reports. DA-08: CI nga checkout i pastër kalon testet me DB; heqja e një guard-i e bllokon merge-in. Arkivo raportet pa sekrete. Pranimi kërkon edhe gate-et: RG-01. Asnjë gate nuk është shënuar Passed nga ky audit. | AC13: Workflow u validua nga lint/lexim dhe konfigurimi lokal ekuivalent kaloi; hosted GitHub Actions nuk u ekzekutua. Validimi 2026-09-08: workflow-i kaloi actionlint dhe tani ndërton/nis image-in e ngurtësuar për E2E; required-check/merge-blocking në GitHub mbetet provë e jashtme. | AD13: .github/workflows/frontend.yml apps/web/server/api/health/ready.get.ts .nvmrc .github/workflows/frontend.yml; Dockerfile; docs/VALIDATION.md | AE13: Pjesërisht — kërkon zhvillim | AF13: Po | AG13: Po, pas implementimit | AH13: Mbeten run hosted, required branch checks, deliberate failing PR dhe gates RLS/secret/container. Workspace nuk ka .git, prandaj merge blocking nuk mund të provohet lokalisht. | AI13: docs/backlog-code-handoff-2026-09-08.json#S0-A09 | AJ13: Programmer A / review: Programmer B
A14: S0-B01 | B14: S0 | C14: Frontend | D14: Bootstrap Nuxt 4 application | E14: Bootstrap Nuxt 4.5.x on Node.js 24 LTS with strict TypeScript, current Nuxt directory structure, runtime config separation, ESLint/typecheck/test scripts and SSR-ready deployment output. | F14: Clean install/build/typecheck passes from lockfile; Node 24 LTS documented; no secret runtime config exposed client-side. | G14: S0-A01 | H14: P0 | I14: Programmer B | J14: Programmer A | K14: 8 | L14: In Review | M14: nuxt build + typecheck | N14: RG-01 | O14: Public/private config separated. | P14: apps/web | Q14: =INDEX('01_ROADMAP'!$C$5:$C$15,MATCH(B14,'01_ROADMAP'!$A$5:$A$15,0)) -> 46272 | R14: =INDEX('01_ROADMAP'!$D$5:$D$15,MATCH(B14,'01_ROADMAP'!$A$5:$A$15,0)) -> 46285 | S14: docs/backlog-partial-progress-2026-09-08.json#S0-B01 | T14: FRONTEND | U14: Platform | V14: GA | W14: See companion DOCX; use Nuxt UI primitives and shared design system for user-facing tasks. | X14: Acceptance Criteria + Test Evidence + Release Gate | Y14: Implementuar — në pranim | Z14: Nuxt 4.5.2/Nuxt UI 4.11.0 me TypeScript strict; .nvmrc tani fikson Node 24. Lint dhe app/server typecheck kalojnë dhe sekretet mbeten server-side. Klasifikimi 2026-09-08: Nuxt/TypeScript/runtime separation është implementuar; pret clean Node 24 build/RG-01. | AA14: Duhet npm ci + production build nga checkout i pastër me Node 24 dhe RG-01. Makina e këtij auditimi po përdor Node 26.5.0. | AB14: Prova e kërkuar nga backlog-u: nuxt build + typecheck Kriteri për t'u verifikuar (nuk deklarohet i kaluar): Clean install/build/typecheck passes from lockfile; Node 24 LTS documented; no secret runtime config exposed client-side. Pranimi kërkon edhe gate-et: RG-01. Asnjë gate nuk është shënuar Passed nga ky audit. | AC14: ESLint exit 0; vue-tsc app exit 0; tsc server exit 0. Clean Node 24 build nuk u ekzekutua. Validimi 2026-09-08: clean npm ci, nuxt typecheck dhe production build kaluan brenda image-it Node 24.20.0 të fiksuar me digest. | AD14: .nvmrc apps/web/package.json apps/web/nuxt.config.ts hq-partials-lint-2.log Dockerfile; .nvmrc; package-lock.json; apps/web/package.json; docs/VALIDATION.md | AE14: Kryer në kod — pret pranim/gate | AF14: Jo për scope-in e rreshtit | AG14: Po | AH14: Duhet npm ci + production build nga checkout i pastër me Node 24 dhe RG-01. Makina e këtij auditimi po përdor Node 26.5.0. | AI14: docs/backlog-code-handoff-2026-09-08.json#S0-B01 | AJ14: Programmer B / review: Programmer A
A15: S0-B02 | B15: S0 | C15: Design System | D15: Create visual tokens and base components | E15: Adopt Nuxt UI v4 as primary component system. Define app.config theme, semantic color/type/spacing/radius/elevation/motion tokens, light/dark variants, icon policy and branded wrappers only where needed. | F15: Tokens drive landing and dashboard; no random feature-level design constants; contrast baseline passes; dark mode has no unreadable states. | G15: S0-B01 | H15: P1 | I15: Programmer B | J15: Programmer A | K15: 9 | L15: In Review | M15: Vitest/component visual QA | N15: RG-14 | O15: Accessible primitives reduce later regressions. | P15: packages/design or web components | Q15: =INDEX('01_ROADMAP'!$C$5:$C$15,MATCH(B15,'01_ROADMAP'!$A$5:$A$15,0)) -> 46272 | R15: =INDEX('01_ROADMAP'!$D$5:$D$15,MATCH(B15,'01_ROADMAP'!$A$5:$A$15,0)) -> 46285 | S15: docs/S0-B02-REPORT-SQ.md | T15: FRONTEND | U15: Platform | V15: GA | W15: See companion DOCX; use Nuxt UI primitives and shared design system for user-facing tasks. | X15: Acceptance Criteria + Test Evidence + Release Gate | Y15: Në review | Z15: U vendos kontrata e përbashkët `--rrit-*` për ngjyra semantike, tipografi, hapësirë, radius, hije dhe motion. Landing dhe dashboard konsumojnë tokenat e UI-së; Nuxt UI v4, Lucide dhe politika e wrapper-ave janë të dokumentuara. Light/dark tokenat dhe testet accessibility u shtuan. | AA15: Mbeten GitHub Actions në PR, review i Programmer A dhe RG-14. Testi i dashboard accessibility krijon të dhëna sintetike dhe duhet të ekzekutohet vetëm në ambient të dedikuar/CI, jo kundër Supabase v1. | AB15: Kriteri lokal i verifikuar: tokenat përdoren për UI standarde në landing dhe dashboard; light/dark accessibility baseline kalon për landing. Ilustrimet e landing-ut lejohen të mbajnë ngjyra/gradientë lokalë sepse janë art-direction, jo konstante të UI-së. RG-14 nuk është shënuar Passed. | AC15: 2026-09-09: `npm.cmd run check` kaloi (toolchain, ESLint, Nuxt typecheck, 27/27 Vitest unit); `npm.cmd run build` kaloi; Playwright landing desktop kaloi 13/13 me kontroll light/dark. `git diff --check` kaloi. | AD15: apps/web/app/assets/css/main.css apps/web/app/assets/css/landing.css apps/web/app/utils/design-system.ts apps/web/app/app.config.ts apps/web/tests/unit/design-system.test.ts apps/web/tests/e2e/accessibility-baseline.spec.ts docs/S0-B02-REPORT-SQ.md | AE15: Në review — implementimi dhe validimi lokal u kryen; CI/review/RG-14 mbeten. | AF15: Po | AG15: Po, pas implementimit | AH15: Ka ende konstante stili në komponentë; duhet rishikim kontrasti/dark mode dhe provë vizuale e versionit aktual. | AI15: docs/backlog-code-handoff-2026-09-08.json#S0-B02 | AJ15: Programmer B / review: Programmer A
A16: S0-B03 | B16: S0 | C16: Frontend | D16: Build authenticated application shell | E16: Build dashboard shell using Nuxt UI DashboardGroup/DashboardSidebar/DashboardNavbar/DashboardToolbar/DashboardSearch with persistent collapse state, org/brand switcher slots and mobile navigation. | F16: Desktop/tablet/mobile shell is keyboard accessible; navigation persists correctly; active org/brand context visible; no layout shift blocker. | G16: S0-B01,S0-B02 | H16: P0 | I16: Programmer B | J16: Programmer A | K16: 8 | L16: In Review | M16: component + Playwright shell smoke | N16: RG-14 | O16: No auth decisions trusted only to UI. | P16: app layout | Q16: =INDEX('01_ROADMAP'!$C$5:$C$15,MATCH(B16,'01_ROADMAP'!$A$5:$A$15,0)) -> 46272 | R16: =INDEX('01_ROADMAP'!$D$5:$D$15,MATCH(B16,'01_ROADMAP'!$A$5:$A$15,0)) -> 46285 | S16: docs/backlog-deep-audit-2026-09-07.json#S0-B03 | T16: FRONTEND | U16: Auth | V16: GA | W16: See companion DOCX; use Nuxt UI primitives and shared design system for user-facing tasks. | X16: Acceptance Criteria + Test Evidence + Release Gate | Y16: Implementuar — në pranim | Z16: Shell me USidebar/UDashboardPanel, navigim, kërkim, kontekst biznesi real, collapse dhe pamje mobile. | AA16: 1. Për scope-in me një biznes për pronar, kodi është implementuar. Mbeten pranim i plotë keyboard/tablet/a11y dhe RG-14; multi-org switcher është jashtë rrjedhës aktuale. | AB16: Prova e kërkuar nga backlog-u: component + Playwright shell smoke Kriteri për t'u verifikuar (nuk deklarohet i kaluar): Desktop/tablet/mobile shell is keyboard accessible; navigation persists correctly; active org/brand context visible; no layout shift blocker. Pranimi kërkon edhe gate-et: RG-14. Asnjë gate nuk është shënuar Passed nga ky audit. | AC16: hq-deep-audit-live-e2e-rerun.log: 4/4. Business/media/validation/revision conflict dhe pagination 13 postime; axe dhe overflow në overview/content/gallery/calendar/social-posts/billing/settings-security, 1440px/390px Chromium. Nuk është Firefox/WebKit/real-device/fault/UAT matrix. | AD16: apps/web/app/layouts/dashboard.vue apps/web/app/components/DashboardPage.vue hq-optional-e2e.log | AE16: Kryer në kod — pret pranim/gate | AF16: Jo për scope-in e rreshtit | AG16: Po | AH16: Për scope-in me një biznes për pronar, kodi është implementuar. Mbeten pranim i plotë keyboard/tablet/a11y dhe RG-14; multi-org switcher është jashtë rrjedhës aktuale. | AI16: docs/backlog-code-handoff-2026-09-08.json#S0-B03 | AJ16: Programmer B / review: Programmer A
... A189: S10-B05 | B189: S10 | C189: Recommendation UX | D189: Polish AI next-actions with feedback controls | E189: Show 3-5 ranked actions, reason, expected benefit caveat, do/dismiss/later controls and links to artifact creation. | F189: No endless feed; dismiss works; action state survives refresh; screen reader announces updates. | G189: S10-A05,S6-B10 | H189: P2 | I189: Programmer B | J189: Programmer A | K189: 6 | L189: Deferred | M189: E2E + a11y | N189: Post-GA | O189: Do not overstate predicted performance. | P189: next-action UX | Q189: =INDEX('01_ROADMAP'!$C$5:$C$15,MATCH(B189,'01_ROADMAP'!$A$5:$A$15,0)) -> 46412 | R189: =INDEX('01_ROADMAP'!$D$5:$D$15,MATCH(B189,'01_ROADMAP'!$A$5:$A$15,0)) -> 46425 | S189: docs/backlog-deep-audit-2026-09-07.json#S10-B05 | T189: FRONTEND | U189: Dashboard | V189: Growth | W189: Card/Badge/Dropdown/Toast. | X189: E2E + a11y | Y189: Shtyrë | Z189: Overview ka next-actions të thjeshta nga gjendja; AI ranking/feedback/fatigue suppression mbetet S10. | AA189: 1. Pas ranking API: shfaq 3–5 veprime me arsye/benefit caveat dhe do/dismiss/later; ruaj gjendjen pas refresh, link tek artefakti dhe njoftim screen-reader. | AB189: Prova e kërkuar nga backlog-u: E2E + a11y Kriteri për t'u verifikuar (nuk deklarohet i kaluar): No endless feed; dismiss works; action state survives refresh; screen reader announces updates. Pranimi kërkon edhe gate-et: Post-GA. Asnjë gate nuk është shënuar Passed nga ky audit. | AC189: Shtyrë sipas scope-it; nuk është realizuar. Kriteret dhe hapat e këtij rreshti vlejnë kur moduli të rikthehet në scope. | AD189: Nuk u gjet implementim specifik; shiko kriterin dhe hapat në AA/AB. | AE189: Shtyrë nga scope-i aktual | AF189: Jo në scope-in posts-only | AG189: Jo tani | AH189: Pas ranking API: shfaq 3–5 veprime me arsye/benefit caveat dhe do/dismiss/later; ruaj gjendjen pas refresh, link tek artefakti dhe njoftim screen-reader. | AI189: docs/backlog-code-handoff-2026-09-08.json#S10-B05 | AJ189: Programmer B / review: Programmer A

Sheet 03_WORKLOAD
A1: Developer Workload & Capacity
A2: Utilization is planned task hours / nominal capacity. Remaining capacity is intentional for review, planning, defects, provider work and stabilization.
A4: Sprint | B4: A Hours | C4: A Capacity | D4: A Util. | E4: B Hours | F4: B Capacity | G4: B Util. | H4: Total | I4: Total Capacity | J4: Buffer | K4: Open P0
A5: S0 | B5: =SUMIFS('02_BACKLOG'!$K:$K,'02_BACKLOG'!$B:$B,$A5,'02_BACKLOG'!$I:$I,"Programmer A") -> 71 | C5: ='00_README'!$B$16 -> 80 | D5: =IFERROR(B5/C5,0) -> 0.8875 | E5: =SUMIFS('02_BACKLOG'!$K:$K,'02_BACKLOG'!$B:$B,$A5,'02_BACKLOG'!$I:$I,"Programmer B") -> 71 | F5: ='00_README'!$B$16 -> 80 | G5: =IFERROR(E5/F5,0) -> 0.8875 | H5: =B5+E5 -> 142 | I5: =C5+F5 -> 160 | J5: =I5-H5 -> 18 | K5: =COUNTIFS('02_BACKLOG'!$B:$B,$A5,'02_BACKLOG'!$H:$H,"P0",'02_BACKLOG'!$L:$L,"<>Done",'02_BACKLOG'!$L:$L,"<>Deferred") -> 14
A6: S1 | B6: =SUMIFS('02_BACKLOG'!$K:$K,'02_BACKLOG'!$B:$B,$A6,'02_BACKLOG'!$I:$I,"Programmer A") -> 72 | C6: ='00_README'!$B$16 -> 80 | D6: =IFERROR(B6/C6,0) -> 0.9 | E6: =SUMIFS('02_BACKLOG'!$K:$K,'02_BACKLOG'!$B:$B,$A6,'02_BACKLOG'!$I:$I,"Programmer B") -> 71 | F6: ='00_README'!$B$16 -> 80 | G6: =IFERROR(E6/F6,0) -> 0.8875 | H6: =B6+E6 -> 143 | I6: =C6+F6 -> 160 | J6: =I6-H6 -> 17 | K6: =COUNTIFS('02_BACKLOG'!$B:$B,$A6,'02_BACKLOG'!$H:$H,"P0",'02_BACKLOG'!$L:$L,"<>Done",'02_BACKLOG'!$L:$L,"<>Deferred") -> 9
A7: S2 | B7: =SUMIFS('02_BACKLOG'!$K:$K,'02_BACKLOG'!$B:$B,$A7,'02_BACKLOG'!$I:$I,"Programmer A") -> 75 | C7: ='00_README'!$B$16 -> 80 | D7: =IFERROR(B7/C7,0) -> 0.9375 | E7: =SUMIFS('02_BACKLOG'!$K:$K,'02_BACKLOG'!$B:$B,$A7,'02_BACKLOG'!$I:$I,"Programmer B") -> 70 | F7: ='00_README'!$B$16 -> 80 | G7: =IFERROR(E7/F7,0) -> 0.875 | H7: =B7+E7 -> 145 | I7: =C7+F7 -> 160 | J7: =I7-H7 -> 15 | K7: =COUNTIFS('02_BACKLOG'!$B:$B,$A7,'02_BACKLOG'!$H:$H,"P0",'02_BACKLOG'!$L:$L,"<>Done",'02_BACKLOG'!$L:$L,"<>Deferred") -> 15
A8: S3 | B8: =SUMIFS('02_BACKLOG'!$K:$K,'02_BACKLOG'!$B:$B,$A8,'02_BACKLOG'!$I:$I,"Programmer A") -> 74 | C8: ='00_README'!$B$16 -> 80 | D8: =IFERROR(B8/C8,0) -> 0.925 | E8: =SUMIFS('02_BACKLOG'!$K:$K,'02_BACKLOG'!$B:$B,$A8,'02_BACKLOG'!$I:$I,"Programmer B") -> 76 | F8: ='00_README'!$B$16 -> 80 | G8: =IFERROR(E8/F8,0) -> 0.95 | H8: =B8+E8 -> 150 | I8: =C8+F8 -> 160 | J8: =I8-H8 -> 10 | K8: =COUNTIFS('02_BACKLOG'!$B:$B,$A8,'02_BACKLOG'!$H:$H,"P0",'02_BACKLOG'!$L:$L,"<>Done",'02_BACKLOG'!$L:$L,"<>Deferred") -> 15
A9: S4 | B9: =SUMIFS('02_BACKLOG'!$K:$K,'02_BACKLOG'!$B:$B,$A9,'02_BACKLOG'!$I:$I,"Programmer A") -> 72 | C9: ='00_README'!$B$16 -> 80 | D9: =IFERROR(B9/C9,0) -> 0.9 | E9: =SUMIFS('02_BACKLOG'!$K:$K,'02_BACKLOG'!$B:$B,$A9,'02_BACKLOG'!$I:$I,"Programmer B") -> 73 | F9: ='00_README'!$B$16 -> 80 | G9: =IFERROR(E9/F9,0) -> 0.9125 | H9: =B9+E9 -> 145 | I9: =C9+F9 -> 160 | J9: =I9-H9 -> 15 | K9: =COUNTIFS('02_BACKLOG'!$B:$B,$A9,'02_BACKLOG'!$H:$H,"P0",'02_BACKLOG'!$L:$L,"<>Done",'02_BACKLOG'!$L:$L,"<>Deferred") -> 14
A10: S5 | B10: =SUMIFS('02_BACKLOG'!$K:$K,'02_BACKLOG'!$B:$B,$A10,'02_BACKLOG'!$I:$I,"Programmer A") -> 73 | C10: ='00_README'!$B$16 -> 80 | D10: =IFERROR(B10/C10,0) -> 0.9125 | E10: =SUMIFS('02_BACKLOG'!$K:$K,'02_BACKLOG'!$B:$B,$A10,'02_BACKLOG'!$I:$I,"Programmer B") -> 69 | F10: ='00_README'!$B$16 -> 80 | G10: =IFERROR(E10/F10,0) -> 0.8625 | H10: =B10+E10 -> 142 | I10: =C10+F10 -> 160 | J10: =I10-H10 -> 18 | K10: =COUNTIFS('02_BACKLOG'!$B:$B,$A10,'02_BACKLOG'!$H:$H,"P0",'02_BACKLOG'!$L:$L,"<>Done",'02_BACKLOG'!$L:$L,"<>Deferred") -> 10
A11: S6 | B11: =SUMIFS('02_BACKLOG'!$K:$K,'02_BACKLOG'!$B:$B,$A11,'02_BACKLOG'!$I:$I,"Programmer A") -> 81 | C11: ='00_README'!$B$16 -> 80 | D11: =IFERROR(B11/C11,0) -> 1.0125 | E11: =SUMIFS('02_BACKLOG'!$K:$K,'02_BACKLOG'!$B:$B,$A11,'02_BACKLOG'!$I:$I,"Programmer B") -> 71 | F11: ='00_README'!$B$16 -> 80 | G11: =IFERROR(E11/F11,0) -> 0.8875 | H11: =B11+E11 -> 152 | I11: =C11+F11 -> 160 | J11: =I11-H11 -> 8 | K11: =COUNTIFS('02_BACKLOG'!$B:$B,$A11,'02_BACKLOG'!$H:$H,"P0",'02_BACKLOG'!$L:$L,"<>Done",'02_BACKLOG'!$L:$L,"<>Deferred") -> 10
A12: S7 | B12: =SUMIFS('02_BACKLOG'!$K:$K,'02_BACKLOG'!$B:$B,$A12,'02_BACKLOG'!$I:$I,"Programmer A") -> 83 | C12: ='00_README'!$B$16 -> 80 | D12: =IFERROR(B12/C12,0) -> 1.0375 | E12: =SUMIFS('02_BACKLOG'!$K:$K,'02_BACKLOG'!$B:$B,$A12,'02_BACKLOG'!$I:$I,"Programmer B") -> 70 | F12: ='00_README'!$B$16 -> 80 | G12: =IFERROR(E12/F12,0) -> 0.875 | H12: =B12+E12 -> 153 | I12: =C12+F12 -> 160 | J12: =I12-H12 -> 7 | K12: =COUNTIFS('02_BACKLOG'!$B:$B,$A12,'02_BACKLOG'!$H:$H,"P0",'02_BACKLOG'!$L:$L,"<>Done",'02_BACKLOG'!$L:$L,"<>Deferred") -> 13
A13: S8 | B13: =SUMIFS('02_BACKLOG'!$K:$K,'02_BACKLOG'!$B:$B,$A13,'02_BACKLOG'!$I:$I,"Programmer A") -> 50 | C13: ='00_README'!$B$16 -> 80 | D13: =IFERROR(B13/C13,0) -> 0.625 | E13: =SUMIFS('02_BACKLOG'!$K:$K,'02_BACKLOG'!$B:$B,$A13,'02_BACKLOG'!$I:$I,"Programmer B") -> 66 | F13: ='00_README'!$B$16 -> 80 | G13: =IFERROR(E13/F13,0) -> 0.825 | H13: =B13+E13 -> 116 | I13: =C13+F13 -> 160 | J13: =I13-H13 -> 44 | K13: =COUNTIFS('02_BACKLOG'!$B:$B,$A13,'02_BACKLOG'!$H:$H,"P0",'02_BACKLOG'!$L:$L,"<>Done",'02_BACKLOG'!$L:$L,"<>Deferred") -> 14
A14: S9 | B14: =SUMIFS('02_BACKLOG'!$K:$K,'02_BACKLOG'!$B:$B,$A14,'02_BACKLOG'!$I:$I,"Programmer A") -> 41 | C14: ='00_README'!$B$16 -> 80 | D14: =IFERROR(B14/C14,0) -> 0.5125 | E14: =SUMIFS('02_BACKLOG'!$K:$K,'02_BACKLOG'!$B:$B,$A14,'02_BACKLOG'!$I:$I,"Programmer B") -> 44 | F14: ='00_README'!$B$16 -> 80 | G14: =IFERROR(E14/F14,0) -> 0.55 | H14: =B14+E14 -> 85 | I14: =C14+F14 -> 160 | J14: =I14-H14 -> 75 | K14: =COUNTIFS('02_BACKLOG'!$B:$B,$A14,'02_BACKLOG'!$H:$H,"P0",'02_BACKLOG'!$L:$L,"<>Done",'02_BACKLOG'!$L:$L,"<>Deferred") -> 0
A15: S10 | B15: =SUMIFS('02_BACKLOG'!$K:$K,'02_BACKLOG'!$B:$B,$A15,'02_BACKLOG'!$I:$I,"Programmer A") -> 38 | C15: ='00_README'!$B$16 -> 80 | D15: =IFERROR(B15/C15,0) -> 0.475 | E15: =SUMIFS('02_BACKLOG'!$K:$K,'02_BACKLOG'!$B:$B,$A15,'02_BACKLOG'!$I:$I,"Programmer B") -> 38 | F15: ='00_README'!$B$16 -> 80 | G15: =IFERROR(E15/F15,0) -> 0.475 | H15: =B15+E15 -> 76 | I15: =C15+F15 -> 160 | J15: =I15-H15 -> 84 | K15: =COUNTIFS('02_BACKLOG'!$B:$B,$A15,'02_BACKLOG'!$H:$H,"P0",'02_BACKLOG'!$L:$L,"<>Done",'02_BACKLOG'!$L:$L,"<>Deferred") -> 0
A17: TOTAL | B17: =SUM(B5:B15) -> 730 | E17: =SUM(E5:E15) -> 719 | H17: =SUM(H5:H15) -> 1449 | I17: =SUM(I5:I15) -> 1760 | J17: =SUM(J5:J15) -> 311 | K17: =SUM(K5:K15) -> 114

Sheet 04_RELEASE_GATES
A1: Release Gates - Production Launch Cannot Bypass These
A2: Gate status is controlled by evidence, not calendar date. Open related P0 tasks are calculated from 02_BACKLOG.
A4: Gate | B4: Name | C4: Purpose | D4: Pass Criteria / Evidence | E4: Related Task Count | F4: Open Related Tasks | G4: Status | H4: Evidence Link | I4: Owner/Notes
A5: RG-01 | B5: Architecture & Build | C5: Architecture baseline, reproducible builds and safe delivery | D5: ADR-001 accepted; repo/build/container reproducible; deployment artifacts immutable. | E5: =COUNTIF('02_BACKLOG'!$N:$N,"*"&A5&"*") -> 10 | F5: =COUNTIFS('02_BACKLOG'!$N:$N,"*"&A5&"*",'02_BACKLOG'!$L:$L,"<>Done",'02_BACKLOG'!$L:$L,"<>Deferred") -> 10 | G5: In Progress | H5: docs/backlog-audit-2026-09-07.json | I5: 2026-09-07: Nuxt/Nitro/PG kod dhe kontrolle lokale; mungon ADR i stack-ut aktual, Node 24/build aktual, CI me DB dhe immutable deploy.
A6: RG-02 | B6: Tenant Isolation | C6: Zero cross-tenant access | D6: All tenant tables RLS protected; negative cross-tenant suite green. | E6: =COUNTIF('02_BACKLOG'!$N:$N,"*"&A6&"*") -> 8 | F6: =COUNTIFS('02_BACKLOG'!$N:$N,"*"&A6&"*",'02_BACKLOG'!$L:$L,"<>Done",'02_BACKLOG'!$L:$L,"<>Deferred") -> 5 | G6: Not Started | H6: docs/backlog-audit-2026-09-07.json | I6: 2026-09-07: Owner checks në aplikacion ekzistojnë; RLS/runtime role/context dhe suite për të gjitha tabelat nuk janë implementuar.
A7: RG-03 | B7: Auth & RBAC | C7: Identity/authorization trustworthy | D7: Role matrix green; sensitive actions audited; no service credential in browser. | E7: =COUNTIF('02_BACKLOG'!$N:$N,"*"&A7&"*") -> 12 | F7: =COUNTIFS('02_BACKLOG'!$N:$N,"*"&A7&"*",'02_BACKLOG'!$L:$L,"<>Done",'02_BACKLOG'!$L:$L,"<>Deferred") -> 8 | G7: In Progress | H7: docs/backlog-audit-2026-09-07.json | I7: 2026-09-07: Better Auth real dhe origin checks; mungojnë role matrix, sensitive-action audit dhe staging auth suite e plotë.
